{
 "cells": [
  {
   "cell_type": "code",
   "execution_count": 3,
   "id": "ccb45a50-3f36-47c2-b901-2fa1de6c4a63",
   "metadata": {},
   "outputs": [
    {
     "name": "stdout",
     "output_type": "stream",
     "text": [
      "Requirement already satisfied: pandas in /usr/local/lib/python3.11/site-packages (2.1.1)\n",
      "Requirement already satisfied: pyodbc in /usr/local/lib/python3.11/site-packages (5.0.1)\n",
      "Requirement already satisfied: numpy>=1.23.2 in /usr/local/lib/python3.11/site-packages (from pandas) (1.26.0)\n",
      "Requirement already satisfied: python-dateutil>=2.8.2 in /usr/local/lib/python3.11/site-packages (from pandas) (2.8.2)\n",
      "Requirement already satisfied: pytz>=2020.1 in /usr/local/lib/python3.11/site-packages (from pandas) (2023.3.post1)\n",
      "Requirement already satisfied: tzdata>=2022.1 in /usr/local/lib/python3.11/site-packages (from pandas) (2023.3)\n",
      "Requirement already satisfied: six>=1.5 in /usr/local/lib/python3.11/site-packages (from python-dateutil>=2.8.2->pandas) (1.16.0)\n"
     ]
    }
   ],
   "source": [
    "!pip install pandas pyodbc"
   ]
  },
  {
   "cell_type": "code",
   "execution_count": 4,
   "id": "dd3c6ea9-99be-443a-917f-f57751c8b0c7",
   "metadata": {},
   "outputs": [
    {
     "ename": "ImportError",
     "evalue": "dlopen(/usr/local/lib/python3.11/site-packages/pyodbc.cpython-311-darwin.so, 0x0002): Library not loaded: /usr/local/opt/unixodbc/lib/libodbc.2.dylib\n  Referenced from: <0A02ADF8-DF83-320E-8D81-7CD11EF5506C> /usr/local/lib/python3.11/site-packages/pyodbc.cpython-311-darwin.so\n  Reason: tried: '/usr/local/opt/unixodbc/lib/libodbc.2.dylib' (no such file), '/System/Volumes/Preboot/Cryptexes/OS/usr/local/opt/unixodbc/lib/libodbc.2.dylib' (no such file), '/usr/local/opt/unixodbc/lib/libodbc.2.dylib' (no such file), '/usr/local/lib/libodbc.2.dylib' (no such file), '/usr/lib/libodbc.2.dylib' (no such file, not in dyld cache)",
     "output_type": "error",
     "traceback": [
      "\u001b[0;31m---------------------------------------------------------------------------\u001b[0m",
      "\u001b[0;31mImportError\u001b[0m                               Traceback (most recent call last)",
      "Cell \u001b[0;32mIn[4], line 2\u001b[0m\n\u001b[1;32m      1\u001b[0m \u001b[38;5;28;01mimport\u001b[39;00m \u001b[38;5;21;01mpandas\u001b[39;00m \u001b[38;5;28;01mas\u001b[39;00m \u001b[38;5;21;01mpd\u001b[39;00m\n\u001b[0;32m----> 2\u001b[0m \u001b[38;5;28;01mimport\u001b[39;00m \u001b[38;5;21;01mpyodbc\u001b[39;00m\n\u001b[1;32m      4\u001b[0m \u001b[38;5;66;03m# Create a Pandas DataFrame (replace this with your actual DataFrame)\u001b[39;00m\n\u001b[1;32m      5\u001b[0m data \u001b[38;5;241m=\u001b[39m {\n\u001b[1;32m      6\u001b[0m     \u001b[38;5;124m'\u001b[39m\u001b[38;5;124mName\u001b[39m\u001b[38;5;124m'\u001b[39m: [\u001b[38;5;124m'\u001b[39m\u001b[38;5;124mJohn\u001b[39m\u001b[38;5;124m'\u001b[39m, \u001b[38;5;124m'\u001b[39m\u001b[38;5;124mJane\u001b[39m\u001b[38;5;124m'\u001b[39m, \u001b[38;5;124m'\u001b[39m\u001b[38;5;124mBob\u001b[39m\u001b[38;5;124m'\u001b[39m],\n\u001b[1;32m      7\u001b[0m     \u001b[38;5;124m'\u001b[39m\u001b[38;5;124mAge\u001b[39m\u001b[38;5;124m'\u001b[39m: [\u001b[38;5;241m25\u001b[39m, \u001b[38;5;241m30\u001b[39m, \u001b[38;5;241m22\u001b[39m],\n\u001b[1;32m      8\u001b[0m     \u001b[38;5;124m'\u001b[39m\u001b[38;5;124mCity\u001b[39m\u001b[38;5;124m'\u001b[39m: [\u001b[38;5;124m'\u001b[39m\u001b[38;5;124mNew York\u001b[39m\u001b[38;5;124m'\u001b[39m, \u001b[38;5;124m'\u001b[39m\u001b[38;5;124mSan Francisco\u001b[39m\u001b[38;5;124m'\u001b[39m, \u001b[38;5;124m'\u001b[39m\u001b[38;5;124mSeattle\u001b[39m\u001b[38;5;124m'\u001b[39m]\n\u001b[1;32m      9\u001b[0m }\n",
      "\u001b[0;31mImportError\u001b[0m: dlopen(/usr/local/lib/python3.11/site-packages/pyodbc.cpython-311-darwin.so, 0x0002): Library not loaded: /usr/local/opt/unixodbc/lib/libodbc.2.dylib\n  Referenced from: <0A02ADF8-DF83-320E-8D81-7CD11EF5506C> /usr/local/lib/python3.11/site-packages/pyodbc.cpython-311-darwin.so\n  Reason: tried: '/usr/local/opt/unixodbc/lib/libodbc.2.dylib' (no such file), '/System/Volumes/Preboot/Cryptexes/OS/usr/local/opt/unixodbc/lib/libodbc.2.dylib' (no such file), '/usr/local/opt/unixodbc/lib/libodbc.2.dylib' (no such file), '/usr/local/lib/libodbc.2.dylib' (no such file), '/usr/lib/libodbc.2.dylib' (no such file, not in dyld cache)"
     ]
    }
   ],
   "source": [
    "import pandas as pd\n",
    "import pyodbc\n",
    "\n",
    "# Create a Pandas DataFrame (replace this with your actual DataFrame)\n",
    "data = {\n",
    "    'Name': ['John', 'Jane', 'Bob'],\n",
    "    'Age': [25, 30, 22],\n",
    "    'City': ['New York', 'San Francisco', 'Seattle']\n",
    "}\n",
    "df = pd.DataFrame(data)\n",
    "\n",
    "# SQL Server connection parameters\n",
    "server = 'localhost'\n",
    "database = 'master'\n",
    "username = 'sa'\n",
    "password = 'Passw0rd'\n",
    "driver = '{ODBC Driver 17 for SQL Server}'  # Use the appropriate driver\n",
    "\n",
    "# Create a connection string\n",
    "connection_string = f'DRIVER={driver};SERVER={server};DATABASE={database};UID={username};PWD={password}'\n",
    "\n",
    "# Establish a connection\n",
    "connection = pyodbc.connect(connection_string)\n",
    "\n",
    "# Save DataFrame to SQL Server\n",
    "table_name = 'your_table_name'\n",
    "df.to_sql(table_name, connection, index=False, if_exists='replace')\n",
    "\n",
    "# Close the connection\n",
    "connection.close()"
   ]
  }
 ],
 "metadata": {
  "kernelspec": {
   "display_name": "Python 3 (ipykernel)",
   "language": "python",
   "name": "python3"
  },
  "language_info": {
   "codemirror_mode": {
    "name": "ipython",
    "version": 3
   },
   "file_extension": ".py",
   "mimetype": "text/x-python",
   "name": "python",
   "nbconvert_exporter": "python",
   "pygments_lexer": "ipython3",
   "version": "3.11.4"
  }
 },
 "nbformat": 4,
 "nbformat_minor": 5
}
